[ 2025-09-21 13:39:48,204 ] 42 root - INFO - Read the dataset as dataframe
[ 2025-09-21 13:39:48,233 ] 21 root - INFO - Binary encoding done to create traget variable
[ 2025-09-21 13:39:48,244 ] 25 root - INFO - Date feature extraction done
[ 2025-09-21 13:39:48,244 ] 49 root - INFO - Preprocessing done
[ 2025-09-21 13:39:48,290 ] 56 root - INFO - Ingestion of the data is completed
[ 2025-09-21 13:39:48,304 ] 79 root - INFO - Read train and test data completed
[ 2025-09-21 13:39:48,304 ] 81 root - INFO - Obtaining preprocessing object
[ 2025-09-21 13:39:48,305 ] 59 root - INFO - Categorical columns: ['Blood Pressure', 'Diabetes Status', 'Gender', 'Heart Attack Related to Vaccine', 'Location', 'Pre-existing Conditions', 'Smoking History', 'Vaccine Dose']
[ 2025-09-21 13:39:48,305 ] 60 root - INFO - Numerical columns: ['Age', 'BMI', 'Cholesterol Level', 'Heart Attack Date_day', 'Heart Attack Date_day_of_week', 'Heart Attack Date_is_weekend', 'Heart Attack Date_month', 'Heart Attack Date_quarter', 'Heart Attack Date_year', 'Outcome', 'Patient ID', 'Severity', 'Vaccination Date_day', 'Vaccination Date_day_of_week', 'Vaccination Date_is_weekend', 'Vaccination Date_month', 'Vaccination Date_quarter', 'Vaccination Date_year']
[ 2025-09-21 13:39:48,305 ] 92 root - INFO - Applying preprocessing object on training and testing datasets.
[ 2025-09-21 13:39:48,341 ] 104 root - INFO - Saved preprocessing object.
[ 2025-09-21 13:39:48,342 ] 34 root - INFO - Split training and test input data
[ 2025-09-21 13:40:10,161 ] 8 root - ERROR - Error occured in python script name [/Users/ishmael/Documents/covid_vaccine_risk/src/utils.py] line number [53] error message[
All the 81 fits failed.
It is very likely that your model is misconfigured.
You can try to debug the error by setting error_score='raise'.

Below are more details about the failures:
--------------------------------------------------------------------------------
81 fits failed with the following error:
Traceback (most recent call last):
  File "/Users/ishmael/Documents/covid_vaccine_risk/venv/lib/python3.11/site-packages/sklearn/model_selection/_validation.py", line 866, in _fit_and_score
    estimator.fit(X_train, y_train, **fit_params)
  File "/Users/ishmael/Documents/covid_vaccine_risk/venv/lib/python3.11/site-packages/catboost/core.py", line 5873, in fit
    return self._fit(X, y, cat_features, text_features, embedding_features, None, graph, sample_weight, None, None, None, None, baseline,
           ^^^^^^^^^^^^^^^^^^^^^^^^^^^^^^^^^^^^^^^^^^^^^^^^^^^^^^^^^^^^^^^^^^^^^^^^^^^^^^^^^^^^^^^^^^^^^^^^^^^^^^^^^^^^^^^^^^^^^^^^^^^^^^
  File "/Users/ishmael/Documents/covid_vaccine_risk/venv/lib/python3.11/site-packages/catboost/core.py", line 2410, in _fit
    self._train(
  File "/Users/ishmael/Documents/covid_vaccine_risk/venv/lib/python3.11/site-packages/catboost/core.py", line 1790, in _train
    self._object._train(train_pool, test_pool, params, allow_clear_pool, init_model._object if init_model else None)
  File "_catboost.pyx", line 5017, in _catboost._CatBoost._train
  File "_catboost.pyx", line 5066, in _catboost._CatBoost._train
_catboost.CatBoostError: catboost/libs/metrics/metric.cpp:6930: All train targets are equal
]
[ 2025-09-21 13:40:10,161 ] 8 root - ERROR - Error occured in python script name [/Users/ishmael/Documents/covid_vaccine_risk/src/components/model_trainer.py] line number [88] error message[Error occured in python script name [/Users/ishmael/Documents/covid_vaccine_risk/src/utils.py] line number [53] error message[
All the 81 fits failed.
It is very likely that your model is misconfigured.
You can try to debug the error by setting error_score='raise'.

Below are more details about the failures:
--------------------------------------------------------------------------------
81 fits failed with the following error:
Traceback (most recent call last):
  File "/Users/ishmael/Documents/covid_vaccine_risk/venv/lib/python3.11/site-packages/sklearn/model_selection/_validation.py", line 866, in _fit_and_score
    estimator.fit(X_train, y_train, **fit_params)
  File "/Users/ishmael/Documents/covid_vaccine_risk/venv/lib/python3.11/site-packages/catboost/core.py", line 5873, in fit
    return self._fit(X, y, cat_features, text_features, embedding_features, None, graph, sample_weight, None, None, None, None, baseline,
           ^^^^^^^^^^^^^^^^^^^^^^^^^^^^^^^^^^^^^^^^^^^^^^^^^^^^^^^^^^^^^^^^^^^^^^^^^^^^^^^^^^^^^^^^^^^^^^^^^^^^^^^^^^^^^^^^^^^^^^^^^^^^^^
  File "/Users/ishmael/Documents/covid_vaccine_risk/venv/lib/python3.11/site-packages/catboost/core.py", line 2410, in _fit
    self._train(
  File "/Users/ishmael/Documents/covid_vaccine_risk/venv/lib/python3.11/site-packages/catboost/core.py", line 1790, in _train
    self._object._train(train_pool, test_pool, params, allow_clear_pool, init_model._object if init_model else None)
  File "_catboost.pyx", line 5017, in _catboost._CatBoost._train
  File "_catboost.pyx", line 5066, in _catboost._CatBoost._train
_catboost.CatBoostError: catboost/libs/metrics/metric.cpp:6930: All train targets are equal
]]
